Workbook

Sheet マスタ
A1: オプションNo | B1: 品名 | C1: 値段
A2: 01 | B2: サンルーフ | C2: 50000
A3: 2 | B3: カーナビ | C3: 80000
A4: 10 | B4: フロアマット | C4: 12000

Sheet 入力
A1: 図番番号 | B1: 標準仕様A
A2: 本体価格 | B2: 2500000
A3: オプションNo | C3: 例: 1,2,3
A4: 品目リスト | B4: =E107
A5: オプション合計 | B5: =SUM(C8:C107)
A6: 総合計 | B6: =B2+B5
A7: オプションNo | B7: 品名 | C7: 値段
A8: =IF(B3="","",TRIM(MID(SUBSTITUTE(SUBSTITUTE(SUBSTITUTE(B3&"","、",","),"，",",")&",",",",REPT(" ",20)),1,20))) | B8: =IF(A8="","",IFERROR(INDEX(マスタ!$B$2:$B$4,MATCH(A8&"",マスタ!$A$2:$A$4,0)),"該当なし")) | C8: =IF(A8="","",IFERROR(INDEX(マスタ!$C$2:$C$4,MATCH(A8&"",マスタ!$A$2:$A$4,0)),"")) | E8: =IF(B8="","",B8)
A9: =IF(B3="","",TRIM(MID(SUBSTITUTE(SUBSTITUTE(SUBSTITUTE(B3&"","、",","),"，",",")&",",",",REPT(" ",20)),21,20))) | B9: =IF(A9="","",IFERROR(INDEX(マスタ!$B$2:$B$4,MATCH(A9&"",マスタ!$A$2:$A$4,0)),"該当なし")) | C9: =IF(A9="","",IFERROR(INDEX(マスタ!$C$2:$C$4,MATCH(A9&"",マスタ!$A$2:$A$4,0)),"")) | E9: =IF(B9="",E8,IF(E8="",B9,E8&","&B9))
A10: =IF(B3="","",TRIM(MID(SUBSTITUTE(SUBSTITUTE(SUBSTITUTE(B3&"","、",","),"，",",")&",",",",REPT(" ",20)),41,20))) | B10: =IF(A10="","",IFERROR(INDEX(マスタ!$B$2:$B$4,MATCH(A10&"",マスタ!$A$2:$A$4,0)),"該当なし")) | C10: =IF(A10="","",IFERROR(INDEX(マスタ!$C$2:$C$4,MATCH(A10&"",マスタ!$A$2:$A$4,0)),"")) | E10: =IF(B10="",E9,IF(E9="",B10,E9&","&B10))
A11: =IF(B3="","",TRIM(MID(SUBSTITUTE(SUBSTITUTE(SUBSTITUTE(B3&"","、",","),"，",",")&",",",",REPT(" ",20)),61,20))) | B11: =IF(A11="","",IFERROR(INDEX(マスタ!$B$2:$B$4,MATCH(A11&"",マスタ!$A$2:$A$4,0)),"該当なし")) | C11: =IF(A11="","",IFERROR(INDEX(マスタ!$C$2:$C$4,MATCH(A11&"",マスタ!$A$2:$A$4,0)),"")) | E11: =IF(B11="",E10,IF(E10="",B11,E10&","&B11))
A12: =IF(B3="","",TRIM(MID(SUBSTITUTE(SUBSTITUTE(SUBSTITUTE(B3&"","、",","),"，",",")&",",",",REPT(" ",20)),81,20))) | B12: =IF(A12="","",IFERROR(INDEX(マスタ!$B$2:$B$4,MATCH(A12&"",マスタ!$A$2:$A$4,0)),"該当なし")) | C12: =IF(A12="","",IFERROR(INDEX(マスタ!$C$2:$C$4,MATCH(A12&"",マスタ!$A$2:$A$4,0)),"")) | E12: =IF(B12="",E11,IF(E11="",B12,E11&","&B12))
A13: =IF(B3="","",TRIM(MID(SUBSTITUTE(SUBSTITUTE(SUBSTITUTE(B3&"","、",","),"，",",")&",",",",REPT(" ",20)),101,20))) | B13: =IF(A13="","",IFERROR(INDEX(マスタ!$B$2:$B$4,MATCH(A13&"",マスタ!$A$2:$A$4,0)),"該当なし")) | C13: =IF(A13="","",IFERROR(INDEX(マスタ!$C$2:$C$4,MATCH(A13&"",マスタ!$A$2:$A$4,0)),"")) | E13: =IF(B13="",E12,IF(E12="",B13,E12&","&B13))
A14: =IF(B3="","",TRIM(MID(SUBSTITUTE(SUBSTITUTE(SUBSTITUTE(B3&"","、",","),"，",",")&",",",",REPT(" ",20)),121,20))) | B14: =IF(A14="","",IFERROR(INDEX(マスタ!$B$2:$B$4,MATCH(A14&"",マスタ!$A$2:$A$4,0)),"該当なし")) | C14: =IF(A14="","",IFERROR(INDEX(マスタ!$C$2:$C$4,MATCH(A14&"",マスタ!$A$2:$A$4,0)),"")) | E14: =IF(B14="",E13,IF(E13="",B14,E13&","&B14))
A15: =IF(B3="","",TRIM(MID(SUBSTITUTE(SUBSTITUTE(SUBSTITUTE(B3&"","、",","),"，",",")&",",",",REPT(" ",20)),141,20))) | B15: =IF(A15="","",IFERROR(INDEX(マスタ!$B$2:$B$4,MATCH(A15&"",マスタ!$A$2:$A$4,0)),"該当なし")) | C15: =IF(A15="","",IFERROR(INDEX(マスタ!$C$2:$C$4,MATCH(A15&"",マスタ!$A$2:$A$4,0)),"")) | E15: =IF(B15="",E14,IF(E14="",B15,E14&","&B15))
A16: =IF(B3="","",TRIM(MID(SUBSTITUTE(SUBSTITUTE(SUBSTITUTE(B3&"","、",","),"，",",")&",",",",REPT(" ",20)),161,20))) | B16: =IF(A16="","",IFERROR(INDEX(マスタ!$B$2:$B$4,MATCH(A16&"",マスタ!$A$2:$A$4,0)),"該当なし")) | C16: =IF(A16="","",IFERROR(INDEX(マスタ!$C$2:$C$4,MATCH(A16&"",マスタ!$A$2:$A$4,0)),"")) | E16: =IF(B16="",E15,IF(E15="",B16,E15&","&B16))
A17: =IF(B3="","",TRIM(MID(SUBSTITUTE(SUBSTITUTE(SUBSTITUTE(B3&"","、",","),"，",",")&",",",",REPT(" ",20)),181,20))) | B17: =IF(A17="","",IFERROR(INDEX(マスタ!$B$2:$B$4,MATCH(A17&"",マスタ!$A$2:$A$4,0)),"該当なし")) | C17: =IF(A17="","",IFERROR(INDEX(マスタ!$C$2:$C$4,MATCH(A17&"",マスタ!$A$2:$A$4,0)),"")) | E17: =IF(B17="",E16,IF(E16="",B17,E16&","&B17))
A18: =IF(B3="","",TRIM(MID(SUBSTITUTE(SUBSTITUTE(SUBSTITUTE(B3&"","、",","),"，",",")&",",",",REPT(" ",20)),201,20))) | B18: =IF(A18="","",IFERROR(INDEX(マスタ!$B$2:$B$4,MATCH(A18&"",マスタ!$A$2:$A$4,0)),"該当なし")) | C18: =IF(A18="","",IFERROR(INDEX(マスタ!$C$2:$C$4,MATCH(A18&"",マスタ!$A$2:$A$4,0)),"")) | E18: =IF(B18="",E17,IF(E17="",B18,E17&","&B18))
A19: =IF(B3="","",TRIM(MID(SUBSTITUTE(SUBSTITUTE(SUBSTITUTE(B3&"","、",","),"，",",")&",",",",REPT(" ",20)),221,20))) | B19: =IF(A19="","",IFERROR(INDEX(マスタ!$B$2:$B$4,MATCH(A19&"",マスタ!$A$2:$A$4,0)),"該当なし")) | C19: =IF(A19="","",IFERROR(INDEX(マスタ!$C$2:$C$4,MATCH(A19&"",マスタ!$A$2:$A$4,0)),"")) | E19: =IF(B19="",E18,IF(E18="",B19,E18&","&B19))
A20: =IF(B3="","",TRIM(MID(SUBSTITUTE(SUBSTITUTE(SUBSTITUTE(B3&"","、",","),"，",",")&",",",",REPT(" ",20)),241,20))) | B20: =IF(A20="","",IFERROR(INDEX(マスタ!$B$2:$B$4,MATCH(A20&"",マスタ!$A$2:$A$4,0)),"該当なし")) | C20: =IF(A20="","",IFERROR(INDEX(マスタ!$C$2:$C$4,MATCH(A20&"",マスタ!$A$2:$A$4,0)),"")) | E20: =IF(B20="",E19,IF(E19="",B20,E19&","&B20))
A21: =IF(B3="","",TRIM(MID(SUBSTITUTE(SUBSTITUTE(SUBSTITUTE(B3&"","、",","),"，",",")&",",",",REPT(" ",20)),261,20))) | B21: =IF(A21="","",IFERROR(INDEX(マスタ!$B$2:$B$4,MATCH(A21&"",マスタ!$A$2:$A$4,0)),"該当なし")) | C21: =IF(A21="","",IFERROR(INDEX(マスタ!$C$2:$C$4,MATCH(A21&"",マスタ!$A$2:$A$4,0)),"")) | E21: =IF(B21="",E20,IF(E20="",B21,E20&","&B21))
A22: =IF(B3="","",TRIM(MID(SUBSTITUTE(SUBSTITUTE(SUBSTITUTE(B3&"","、",","),"，",",")&",",",",REPT(" ",20)),281,20))) | B22: =IF(A22="","",IFERROR(INDEX(マスタ!$B$2:$B$4,MATCH(A22&"",マスタ!$A$2:$A$4,0)),"該当なし")) | C22: =IF(A22="","",IFERROR(INDEX(マスタ!$C$2:$C$4,MATCH(A22&"",マスタ!$A$2:$A$4,0)),"")) | E22: =IF(B22="",E21,IF(E21="",B22,E21&","&B22))
A23: =IF(B3="","",TRIM(MID(SUBSTITUTE(SUBSTITUTE(SUBSTITUTE(B3&"","、",","),"，",",")&",",",",REPT(" ",20)),301,20))) | B23: =IF(A23="","",IFERROR(INDEX(マスタ!$B$2:$B$4,MATCH(A23&"",マスタ!$A$2:$A$4,0)),"該当なし")) | C23: =IF(A23="","",IFERROR(INDEX(マスタ!$C$2:$C$4,MATCH(A23&"",マスタ!$A$2:$A$4,0)),"")) | E23: =IF(B23="",E22,IF(E22="",B23,E22&","&B23))
A24: =IF(B3="","",TRIM(MID(SUBSTITUTE(SUBSTITUTE(SUBSTITUTE(B3&"","、",","),"，",",")&",",",",REPT(" ",20)),321,20))) | B24: =IF(A24="","",IFERROR(INDEX(マスタ!$B$2:$B$4,MATCH(A24&"",マスタ!$A$2:$A$4,0)),"該当なし")) | C24: =IF(A24="","",IFERROR(INDEX(マスタ!$C$2:$C$4,MATCH(A24&"",マスタ!$A$2:$A$4,0)),"")) | E24: =IF(B24="",E23,IF(E23="",B24,E23&","&B24))
A25: =IF(B3="","",TRIM(MID(SUBSTITUTE(SUBSTITUTE(SUBSTITUTE(B3&"","、",","),"，",",")&",",",",REPT(" ",20)),341,20))) | B25: =IF(A25="","",IFERROR(INDEX(マスタ!$B$2:$B$4,MATCH(A25&"",マスタ!$A$2:$A$4,0)),"該当なし")) | C25: =IF(A25="","",IFERROR(INDEX(マスタ!$C$2:$C$4,MATCH(A25&"",マスタ!$A$2:$A$4,0)),"")) | E25: =IF(B25="",E24,IF(E24="",B25,E24&","&B25))
A26: =IF(B3="","",TRIM(MID(SUBSTITUTE(SUBSTITUTE(SUBSTITUTE(B3&"","、",","),"，",",")&",",",",REPT(" ",20)),361,20))) | B26: =IF(A26="","",IFERROR(INDEX(マスタ!$B$2:$B$4,MATCH(A26&"",マスタ!$A$2:$A$4,0)),"該当なし")) | C26: =IF(A26="","",IFERROR(INDEX(マスタ!$C$2:$C$4,MATCH(A26&"",マスタ!$A$2:$A$4,0)),"")) | E26: =IF(B26="",E25,IF(E25="",B26,E25&","&B26))
A27: =IF(B3="","",TRIM(MID(SUBSTITUTE(SUBSTITUTE(SUBSTITUTE(B3&"","、",","),"，",",")&",",",",REPT(" ",20)),381,20))) | B27: =IF(A27="","",IFERROR(INDEX(マスタ!$B$2:$B$4,MATCH(A27&"",マスタ!$A$2:$A$4,0)),"該当なし")) | C27: =IF(A27="","",IFERROR(INDEX(マスタ!$C$2:$C$4,MATCH(A27&"",マスタ!$A$2:$A$4,0)),"")) | E27: =IF(B27="",E26,IF(E26="",B27,E26&","&B27))
A28: =IF(B3="","",TRIM(MID(SUBSTITUTE(SUBSTITUTE(SUBSTITUTE(B3&"","、",","),"，",",")&",",",",REPT(" ",20)),401,20))) | B28: =IF(A28="","",IFERROR(INDEX(マスタ!$B$2:$B$4,MATCH(A28&"",マスタ!$A$2:$A$4,0)),"該当なし")) | C28: =IF(A28="","",IFERROR(INDEX(マスタ!$C$2:$C$4,MATCH(A28&"",マスタ!$A$2:$A$4,0)),"")) | E28: =IF(B28="",E27,IF(E27="",B28,E27&","&B28))
A29: =IF(B3="","",TRIM(MID(SUBSTITUTE(SUBSTITUTE(SUBSTITUTE(B3&"","、",","),"，",",")&",",",",REPT(" ",20)),421,20))) | B29: =IF(A29="","",IFERROR(INDEX(マスタ!$B$2:$B$4,MATCH(A29&"",マスタ!$A$2:$A$4,0)),"該当なし")) | C29: =IF(A29="","",IFERROR(INDEX(マスタ!$C$2:$C$4,MATCH(A29&"",マスタ!$A$2:$A$4,0)),"")) | E29: =IF(B29="",E28,IF(E28="",B29,E28&","&B29))
A30: =IF(B3="","",TRIM(MID(SUBSTITUTE(SUBSTITUTE(SUBSTITUTE(B3&"","、",","),"，",",")&",",",",REPT(" ",20)),441,20))) | B30: =IF(A30="","",IFERROR(INDEX(マスタ!$B$2:$B$4,MATCH(A30&"",マスタ!$A$2:$A$4,0)),"該当なし")) | C30: =IF(A30="","",IFERROR(INDEX(マスタ!$C$2:$C$4,MATCH(A30&"",マスタ!$A$2:$A$4,0)),"")) | E30: =IF(B30="",E29,IF(E29="",B30,E29&","&B30))
A31: =IF(B3="","",TRIM(MID(SUBSTITUTE(SUBSTITUTE(SUBSTITUTE(B3&"","、",","),"，",",")&",",",",REPT(" ",20)),461,20))) | B31: =IF(A31="","",IFERROR(INDEX(マスタ!$B$2:$B$4,MATCH(A31&"",マスタ!$A$2:$A$4,0)),"該当なし")) | C31: =IF(A31="","",IFERROR(INDEX(マスタ!$C$2:$C$4,MATCH(A31&"",マスタ!$A$2:$A$4,0)),"")) | E31: =IF(B31="",E30,IF(E30="",B31,E30&","&B31))
A32: =IF(B3="","",TRIM(MID(SUBSTITUTE(SUBSTITUTE(SUBSTITUTE(B3&"","、",","),"，",",")&",",",",REPT(" ",20)),481,20))) | B32: =IF(A32="","",IFERROR(INDEX(マスタ!$B$2:$B$4,MATCH(A32&"",マスタ!$A$2:$A$4,0)),"該当なし")) | C32: =IF(A32="","",IFERROR(INDEX(マスタ!$C$2:$C$4,MATCH(A32&"",マスタ!$A$2:$A$4,0)),"")) | E32: =IF(B32="",E31,IF(E31="",B32,E31&","&B32))
A33: =IF(B3="","",TRIM(MID(SUBSTITUTE(SUBSTITUTE(SUBSTITUTE(B3&"","、",","),"，",",")&",",",",REPT(" ",20)),501,20))) | B33: =IF(A33="","",IFERROR(INDEX(マスタ!$B$2:$B$4,MATCH(A33&"",マスタ!$A$2:$A$4,0)),"該当なし")) | C33: =IF(A33="","",IFERROR(INDEX(マスタ!$C$2:$C$4,MATCH(A33&"",マスタ!$A$2:$A$4,0)),"")) | E33: =IF(B33="",E32,IF(E32="",B33,E32&","&B33))
A34: =IF(B3="","",TRIM(MID(SUBSTITUTE(SUBSTITUTE(SUBSTITUTE(B3&"","、",","),"，",",")&",",",",REPT(" ",20)),521,20))) | B34: =IF(A34="","",IFERROR(INDEX(マスタ!$B$2:$B$4,MATCH(A34&"",マスタ!$A$2:$A$4,0)),"該当なし")) | C34: =IF(A34="","",IFERROR(INDEX(マスタ!$C$2:$C$4,MATCH(A34&"",マスタ!$A$2:$A$4,0)),"")) | E34: =IF(B34="",E33,IF(E33="",B34,E33&","&B34))
A35: =IF(B3="","",TRIM(MID(SUBSTITUTE(SUBSTITUTE(SUBSTITUTE(B3&"","、",","),"，",",")&",",",",REPT(" ",20)),541,20))) | B35: =IF(A35="","",IFERROR(INDEX(マスタ!$B$2:$B$4,MATCH(A35&"",マスタ!$A$2:$A$4,0)),"該当なし")) | C35: =IF(A35="","",IFERROR(INDEX(マスタ!$C$2:$C$4,MATCH(A35&"",マスタ!$A$2:$A$4,0)),"")) | E35: =IF(B35="",E34,IF(E34="",B35,E34&","&B35))
A36: =IF(B3="","",TRIM(MID(SUBSTITUTE(SUBSTITUTE(SUBSTITUTE(B3&"","、",","),"，",",")&",",",",REPT(" ",20)),561,20))) | B36: =IF(A36="","",IFERROR(INDEX(マスタ!$B$2:$B$4,MATCH(A36&"",マスタ!$A$2:$A$4,0)),"該当なし")) | C36: =IF(A36="","",IFERROR(INDEX(マスタ!$C$2:$C$4,MATCH(A36&"",マスタ!$A$2:$A$4,0)),"")) | E36: =IF(B36="",E35,IF(E35="",B36,E35&","&B36))
A37: =IF(B3="","",TRIM(MID(SUBSTITUTE(SUBSTITUTE(SUBSTITUTE(B3&"","、",","),"，",",")&",",",",REPT(" ",20)),581,20))) | B37: =IF(A37="","",IFERROR(INDEX(マスタ!$B$2:$B$4,MATCH(A37&"",マスタ!$A$2:$A$4,0)),"該当なし")) | C37: =IF(A37="","",IFERROR(INDEX(マスタ!$C$2:$C$4,MATCH(A37&"",マスタ!$A$2:$A$4,0)),"")) | E37: =IF(B37="",E36,IF(E36="",B37,E36&","&B37))
A38: =IF(B3="","",TRIM(MID(SUBSTITUTE(SUBSTITUTE(SUBSTITUTE(B3&"","、",","),"，",",")&",",",",REPT(" ",20)),601,20))) | B38: =IF(A38="","",IFERROR(INDEX(マスタ!$B$2:$B$4,MATCH(A38&"",マスタ!$A$2:$A$4,0)),"該当なし")) | C38: =IF(A38="","",IFERROR(INDEX(マスタ!$C$2:$C$4,MATCH(A38&"",マスタ!$A$2:$A$4,0)),"")) | E38: =IF(B38="",E37,IF(E37="",B38,E37&","&B38))
A39: =IF(B3="","",TRIM(MID(SUBSTITUTE(SUBSTITUTE(SUBSTITUTE(B3&"","、",","),"，",",")&",",",",REPT(" ",20)),621,20))) | B39: =IF(A39="","",IFERROR(INDEX(マスタ!$B$2:$B$4,MATCH(A39&"",マスタ!$A$2:$A$4,0)),"該当なし")) | C39: =IF(A39="","",IFERROR(INDEX(マスタ!$C$2:$C$4,MATCH(A39&"",マスタ!$A$2:$A$4,0)),"")) | E39: =IF(B39="",E38,IF(E38="",B39,E38&","&B39))
A40: =IF(B3="","",TRIM(MID(SUBSTITUTE(SUBSTITUTE(SUBSTITUTE(B3&"","、",","),"，",",")&",",",",REPT(" ",20)),641,20))) | B40: =IF(A40="","",IFERROR(INDEX(マスタ!$B$2:$B$4,MATCH(A40&"",マスタ!$A$2:$A$4,0)),"該当なし")) | C40: =IF(A40="","",IFERROR(INDEX(マスタ!$C$2:$C$4,MATCH(A40&"",マスタ!$A$2:$A$4,0)),"")) | E40: =IF(B40="",E39,IF(E39="",B40,E39&","&B40))
...
